<?xml version="1.0" encoding="utf-8"?>
<!-- This URDF was automatically created by SolidWorks to URDF Exporter! Originally created by Stephen Brawner (brawner@gmail.com) 
     Commit Version: 1.6.0-4-g7f85cfe  Build Version: 1.6.7995.38578
     For more information, please see http://wiki.ros.org/sw_urdf_exporter -->
<robot
  name="Assem1">
  <link
    name="base_link">
    <visual>
      <origin
        xyz="0 0 0"
        rpy="0 0 0" />
      <geometry>
        <mesh
          filename="package://robot_description/meshes/base_link.STL" />
      </geometry>
      <material
        name="">
        <color
          rgba="0.79216 0.81961 0.93333 1" />
      </material>
    </visual>
    <collision>
      <origin
        xyz="0 0 0"
        rpy="0 0 0" />
      <geometry>
        <mesh
          filename="package://robot_description/meshes/base_link.STL" />
      </geometry>
    </collision>
  </link>
    <link name="base_inertia">
    <inertial>
      <origin
        xyz="0.0049116 0.00019928 0.035673"
        rpy="0 0 0" />
      <mass
        value="0.11758" />
      <inertia
        ixx="0.00015682"
        ixy="-1.537E-06"
        ixz="3.5348E-06"
        iyy="0.00017869"
        iyz="-1.5402E-08"
        izz="0.00024462" />
    </inertial>
  </link>
  <!-- Fixed joint to add dummy inertia link -->
  <joint name="base_to_base_inertia" type="fixed">
    <parent link="base_link" />
    <child link="base_inertia" />
    <origin rpy="0 0 0" xyz="0 0 0" />
  </joint>
  <link
    name="lc_base_link">
    <inertial>
      <origin
        xyz="0.0005292 0.00019928 -0.041102"
        rpy="0 0 0" />
      <mass
        value="0" />
      <inertia
        ixx="0"
        ixy="0"
        ixz="0"
        iyy="0"
        iyz="0"
        izz="0" />
    </inertial>
    <visual>
      <origin
        xyz="0 0 0"
        rpy="0 0 0" />
      <geometry>
        <mesh
          filename="package://robot_description/meshes/lc_base_link.STL" />
      </geometry>
      <material
        name="">
        <color
          rgba="0.79216 0.81961 0.93333 1" />
      </material>
    </visual>
    <collision>
      <origin
        xyz="0 0 0"
        rpy="0 0 0" />
      <geometry>
        <mesh
          filename="package://robot_description/meshes/lc_base_link.STL" />
      </geometry>
    </collision>
  </link>
  <joint
    name="lc_base_joint"
    type="fixed">
    <origin
      xyz="0.0043824 0 0.076775"
      rpy="0 0 0" />
    <parent
      link="base_link" />
    <child
      link="lc_base_link" />
    <axis
      xyz="0 0 0" />
  </joint>
  <link
    name="servo1_link">
    <inertial>
      <origin
        xyz="0.0090001 0.014697 0.022411"
        rpy="0 0 0" />
      <mass
        value="0.088403" />
      <inertia
        ixx="4.652E-05"
        ixy="-1.8761E-06"
        ixz="-1.0429E-05"
        iyy="6.1759E-05"
        iyz="-4.962E-06"
        izz="5.0271E-05" />
    </inertial>
    <visual>
      <origin
        xyz="0 0 0"
        rpy="0 0 0" />
      <geometry>
        <mesh
          filename="package://robot_description/meshes/servo1_link.STL" />
      </geometry>
      <material
        name="">
        <color
          rgba="0.79216 0.81961 0.93333 1" />
      </material>
    </visual>
    <collision>
      <origin
        xyz="0 0 0"
        rpy="0 0 0" />
      <geometry>
        <mesh
          filename="package://robot_description/meshes/servo1_link.STL" />
      </geometry>
    </collision>
  </link>
  <joint
    name="servo1_joint"
    type="revolute">
    <origin
      xyz="0 0 0"
      rpy="0 0 0" />
    <parent
      link="lc_base_link" />
    <child
      link="servo1_link" />
    <axis
      xyz="-0.056988 0 -0.99837" />
    <limit
      lower="-3.14"
      upper="3.14"
      effort="0.98067"
      velocity="1.6" />
  </joint>
  <link
    name="servo2_link">
    <inertial>
      <origin
        xyz="0.0317 0.038148 0.0072243"
        rpy="0 0 0" />
      <mass
        value="0.054547" />
      <inertia
        ixx="3.3395E-05"
        ixy="-2.1758E-05"
        ixz="2.3866E-07"
        iyy="3.178E-05"
        iyz="-1.6941E-07"
        izz="6.2215E-05" />
    </inertial>
    <visual>
      <origin
        xyz="0 0 0"
        rpy="0 0 0" />
      <geometry>
        <mesh
          filename="package://robot_description/meshes/servo2_link.STL" />
      </geometry>
      <material
        name="">
        <color
          rgba="0.79216 0.81961 0.93333 1" />
      </material>
    </visual>
    <collision>
      <origin
        xyz="0 0 0"
        rpy="0 0 0" />
      <geometry>
        <mesh
          filename="package://robot_description/meshes/servo2_link.STL" />
      </geometry>
    </collision>
  </link>
  <joint
    name="servo2_joint"
    type="revolute">
    <origin
      xyz="0.0054931 0.004 0.021697"
      rpy="1.5708 0 0" />
    <parent
      link="servo1_link" />
    <child
      link="servo2_link" />
    <axis
      xyz="0 0 -1" />
    <limit
      lower="-3.14"
      upper="3.14"
      effort="0.98067"
      velocity="1.6" />
  </joint>
  <link
    name="servo3_link">
    <inertial>
      <origin
        xyz="0.025062 -0.040723 -0.015889"
        rpy="0 0 0" />
      <mass
        value="0.10955" />
      <inertia
        ixx="5.2087E-05"
        ixy="2.0409E-05"
        ixz="-3.8714E-07"
        iyy="3.1485E-05"
        iyz="6.2907E-07"
        izz="6.8049E-05" />
    </inertial>
    <visual>
      <origin
        xyz="0 0 0"
        rpy="0 0 0" />
      <geometry>
        <mesh
          filename="package://robot_description/meshes/servo3_link.STL" />
      </geometry>
      <material
        name="">
        <color
          rgba="0.79216 0.81961 0.93333 1" />
      </material>
    </visual>
    <collision>
      <origin
        xyz="0 0 0"
        rpy="0 0 0" />
      <geometry>
        <mesh
          filename="package://robot_description/meshes/servo3_link.STL" />
      </geometry>
    </collision>
  </link>
  <joint
    name="servo3_joint"
    type="revolute">
    <origin
      xyz="0.069118 0.072269 0"
      rpy="0 0 0" />
    <parent
      link="servo2_link" />
    <child
      link="servo3_link" />
    <axis
      xyz="0 0 -1" />
    <limit
      lower="-3.14"
      upper="3.14"
      effort="0.98067"
      velocity="1.6" />
  </joint>
  <link
    name="servo4_link">
    <inertial>
      <origin
        xyz="0.056342 0.0058296 0.0025327"
        rpy="0 0 0" />
      <mass
        value="0.027699" />
      <inertia
        ixx="1.248E-05"
        ixy="8.8793E-07"
        ixz="4.4735E-07"
        iyy="1.3947E-05"
        iyz="-1.0992E-07"
        izz="1.4673E-05" />
    </inertial>
    <visual>
      <origin
        xyz="0 0 0"
        rpy="0 0 0" />
      <geometry>
        <mesh
          filename="package://robot_description/meshes/servo4_link.STL" />
      </geometry>
      <material
        name="">
        <color
          rgba="0.79216 0.81961 0.93333 1" />
      </material>
    </visual>
    <collision>
      <origin
        xyz="0 0 0"
        rpy="0 0 0" />
      <geometry>
        <mesh
          filename="package://robot_description/meshes/servo4_link.STL" />
      </geometry>
    </collision>
  </link>
  <joint
    name="servo4_joint"
    type="revolute">
    <origin
      xyz="0.049293 -0.080097 0"
      rpy="0 0 0" />
    <parent
      link="servo3_link" />
    <child
      link="servo4_link" />
    <axis
      xyz="0 0 1" />
    <limit
      lower="-3.14"
      upper="3.14"
      effort="0.98067"
      velocity="1.6" />
  </joint>
  <link
    name="servo5_link">
    <inertial>
      <origin
        xyz="0.006688 0.0058716 -0.011122"
        rpy="0 0 0" />
      <mass
        value="0.0077585" />
      <inertia
        ixx="1.3753E-06"
        ixy="-1.1771E-06"
        ixz="1.4655E-09"
        iyy="2.5651E-06"
        iyz="1.5408E-09"
        izz="3.9017E-06" />
    </inertial>
    <visual>
      <origin
        xyz="0 0 0"
        rpy="0 0 0" />
      <geometry>
        <mesh
          filename="package://robot_description/meshes/servo5_link.STL" />
      </geometry>
      <material
        name="">
        <color
          rgba="0.79216 0.81961 0.93333 1" />
      </material>
    </visual>
    <collision>
      <origin
        xyz="0 0 0"
        rpy="0 0 0" />
      <geometry>
        <mesh
          filename="package://robot_description/meshes/servo5_link.STL" />
      </geometry>
    </collision>
  </link>
  <joint
    name="servo5_joint"
    type="revolute">
    <origin
      xyz="0.079403 -0.025473 0.0165"
      rpy="1.5708 0 0" />
    <parent
      link="servo4_link" />
    <child
      link="servo5_link" />
    <axis
      xyz="0 0 1" />
    <limit
      lower="-3.14"
      upper="3.14"
      effort="0.21575"
      velocity="0.1" />
  </joint>
  <link
    name="end2_link">
    <inertial>
      <origin
        xyz="-0.21656 -0.040334 -0.01412"
        rpy="0 0 0" />
      <mass
        value="0" />
      <inertia
        ixx="0"
        ixy="0"
        ixz="0"
        iyy="0"
        iyz="0"
        izz="0" />
    </inertial>
    <visual>
      <origin
        xyz="0 0 0"
        rpy="0 0 0" />
      <geometry>
        <sphere radius="0" />
      </geometry>
      <material
        name="">
        <color
          rgba="1 1 1 1" />
      </material>
    </visual>
    <collision>
      <origin
        xyz="0 0 0"
        rpy="0 0 0" />
      <geometry>
        <sphere radius="0" />
      </geometry>
    </collision>
  </link>
  <joint
    name="end2_joint"
    type="fixed">
    <origin
      xyz="0.066229 0.019559 -0.013973"
      rpy="0 0 0" />
    <parent
      link="servo5_link" />
    <child
      link="end2_link" />
    <axis
      xyz="0 0 0" />
  </joint>
  <link
    name="servo6_link">
    <inertial>
      <origin
        xyz="0.013306 -0.0079039 -0.012559"
        rpy="0 0 0" />
      <mass
        value="0.0065727" />
      <inertia
        ixx="9.684E-07"
        ixy="1.0052E-06"
        ixz="1.886E-22"
        iyy="2.0562E-06"
        iyz="-3.3448E-22"
        izz="2.9915E-06" />
    </inertial>
    <visual>
      <origin
        xyz="0 0 0"
        rpy="0 0 0" />
      <geometry>
        <mesh
          filename="package://robot_description/meshes/servo6_link.STL" />
      </geometry>
      <material
        name="">
        <color
          rgba="0.79216 0.81961 0.93333 1" />
      </material>
    </visual>
    <collision>
      <origin
        xyz="0 0 0"
        rpy="0 0 0" />
      <geometry>
        <mesh
          filename="package://robot_description/meshes/servo6_link.STL" />
      </geometry>
    </collision>
  </link>
  <joint
    name="servo6_joint"
    type="revolute">
    <origin
      xyz="0.076526 -0.025309 -0.0165"
      rpy="1.5708 0 0" />
    <parent
      link="servo4_link" />
    <child
      link="servo6_link" />
    <axis
      xyz="0 0 1" />
    <limit
      lower="-3.14"
      upper="3.14"
      effort="0.21575"
      velocity="0.1" />
  </joint>
  <link
    name="end1_link">
    <inertial>
      <origin
        xyz="-0.21599 0.030977 -0.031841"
        rpy="0 0 0" />
      <mass
        value="0" />
      <inertia
        ixx="0"
        ixy="0"
        ixz="0"
        iyy="0"
        iyz="0"
        izz="0" />
    </inertial>
    <visual>
      <origin
        xyz="0 0 0"
        rpy="0 0 0" />
      <geometry>
        <sphere radius="0" />
      </geometry>
      <material
        name="">
        <color
          rgba="1 1 1 1" />
      </material>
    </visual>
    <collision>
      <origin
        xyz="0 0 0"
        rpy="0 0 0" />
      <geometry>
        <sphere radius="0" />
      </geometry>
    </collision>
  </link>
  <joint
    name="end1_joint"
    type="fixed">
    <origin
      xyz="0.06854 -0.018752 0.0039123"
      rpy="0 0 0" />
    <parent
      link="servo6_link" />
    <child
      link="end1_link" />
    <axis
      xyz="0 0 0" />
  </joint>
</robot>